%YAML 1.1
%TAG !u! tag:unity3d.com,2011:
--- !u!29 &1
OcclusionCullingSettings:
  m_ObjectHideFlags: 0
  serializedVersion: 2
  m_OcclusionBakeSettings:
    smallestOccluder: 5
    smallestHole: 0.25
    backfaceThreshold: 100
  m_SceneGUID: 00000000000000000000000000000000
  m_OcclusionCullingData: {fileID: 0}
--- !u!104 &2
RenderSettings:
  m_ObjectHideFlags: 0
  serializedVersion: 9
  m_Fog: 0
  m_FogColor: {r: 0.5, g: 0.5, b: 0.5, a: 1}
  m_FogMode: 3
  m_FogDensity: 0.01
  m_LinearFogStart: 0
  m_LinearFogEnd: 300
  m_AmbientSkyColor: {r: 0.212, g: 0.227, b: 0.259, a: 1}
  m_AmbientEquatorColor: {r: 0.114, g: 0.125, b: 0.133, a: 1}
  m_AmbientGroundColor: {r: 0.047, g: 0.043, b: 0.035, a: 1}
  m_AmbientIntensity: 1
  m_AmbientMode: 0
  m_SubtractiveShadowColor: {r: 0.42, g: 0.478, b: 0.627, a: 1}
  m_SkyboxMaterial: {fileID: 10304, guid: 0000000000000000f000000000000000, type: 0}
  m_HaloStrength: 0.5
  m_FlareStrength: 1
  m_FlareFadeSpeed: 3
  m_HaloTexture: {fileID: 0}
  m_SpotCookie: {fileID: 10001, guid: 0000000000000000e000000000000000, type: 0}
  m_DefaultReflectionMode: 0
  m_DefaultReflectionResolution: 128
  m_ReflectionBounces: 1
  m_ReflectionIntensity: 1
  m_CustomReflection: {fileID: 0}
  m_Sun: {fileID: 705507994}
  m_IndirectSpecularColor: {r: 0.18028328, g: 0.22571328, b: 0.3069218, a: 1}
  m_UseRadianceAmbientProbe: 0
--- !u!157 &3
LightmapSettings:
  m_ObjectHideFlags: 0
  serializedVersion: 12
  m_GIWorkflowMode: 1
  m_GISettings:
    serializedVersion: 2
    m_BounceScale: 1
    m_IndirectOutputScale: 1
    m_AlbedoBoost: 1
    m_EnvironmentLightingMode: 0
    m_EnableBakedLightmaps: 1
    m_EnableRealtimeLightmaps: 0
  m_LightmapEditorSettings:
    serializedVersion: 12
    m_Resolution: 2
    m_BakeResolution: 40
    m_AtlasSize: 1024
    m_AO: 0
    m_AOMaxDistance: 1
    m_CompAOExponent: 1
    m_CompAOExponentDirect: 0
    m_ExtractAmbientOcclusion: 0
    m_Padding: 2
    m_LightmapParameters: {fileID: 0}
    m_LightmapsBakeMode: 1
    m_TextureCompression: 1
    m_FinalGather: 0
    m_FinalGatherFiltering: 1
    m_FinalGatherRayCount: 256
    m_ReflectionCompression: 2
    m_MixedBakeMode: 2
    m_BakeBackend: 1
    m_PVRSampling: 1
    m_PVRDirectSampleCount: 32
    m_PVRSampleCount: 500
    m_PVRBounces: 2
    m_PVREnvironmentSampleCount: 500
    m_PVREnvironmentReferencePointCount: 2048
    m_PVRFilteringMode: 2
    m_PVRDenoiserTypeDirect: 0
    m_PVRDenoiserTypeIndirect: 0
    m_PVRDenoiserTypeAO: 0
    m_PVRFilterTypeDirect: 0
    m_PVRFilterTypeIndirect: 0
    m_PVRFilterTypeAO: 0
    m_PVREnvironmentMIS: 0
    m_PVRCulling: 1
    m_PVRFilteringGaussRadiusDirect: 1
    m_PVRFilteringGaussRadiusIndirect: 5
    m_PVRFilteringGaussRadiusAO: 2
    m_PVRFilteringAtrousPositionSigmaDirect: 0.5
    m_PVRFilteringAtrousPositionSigmaIndirect: 2
    m_PVRFilteringAtrousPositionSigmaAO: 1
    m_ExportTrainingData: 0
    m_TrainingDataDestination: TrainingData
    m_LightProbeSampleCountMultiplier: 4
  m_LightingDataAsset: {fileID: 0}
  m_LightingSettings: {fileID: 0}
--- !u!196 &4
NavMeshSettings:
  serializedVersion: 2
  m_ObjectHideFlags: 0
  m_BuildSettings:
    serializedVersion: 3
    agentTypeID: 0
    agentRadius: 0.5
    agentHeight: 2
    agentSlope: 45
    agentClimb: 0.4
    ledgeDropHeight: 0
    maxJumpAcrossDistance: 0
    minRegionArea: 2
    manualCellSize: 0
    cellSize: 0.16666667
    manualTileSize: 0
    tileSize: 256
    buildHeightMesh: 0
    maxJobWorkers: 0
    preserveTilesOutsideBounds: 0
    debug:
      m_Flags: 0
  m_NavMeshData: {fileID: 0}
--- !u!1 &297247864
GameObject:
  m_ObjectHideFlags: 0
  m_CorrespondingSourceObject: {fileID: 0}
  m_PrefabInstance: {fileID: 0}
  m_PrefabAsset: {fileID: 0}
  serializedVersion: 6
  m_Component:
  - component: {fileID: 297247865}
  - component: {fileID: 297247867}
  - component: {fileID: 297247866}
  m_Layer: 5
  m_Name: Text (TMP)
  m_TagString: Untagged
  m_Icon: {fileID: 0}
  m_NavMeshLayer: 0
  m_StaticEditorFlags: 0
  m_IsActive: 1
--- !u!224 &297247865
RectTransform:
  m_ObjectHideFlags: 0
  m_CorrespondingSourceObject: {fileID: 0}
  m_PrefabInstance: {fileID: 0}
  m_PrefabAsset: {fileID: 0}
  m_GameObject: {fileID: 297247864}
  m_LocalRotation: {x: 0, y: 0, z: 0, w: 1}
  m_LocalPosition: {x: 0, y: 0, z: 0}
  m_LocalScale: {x: 1, y: 1, z: 1}
  m_ConstrainProportionsScale: 0
  m_Children: []
  m_Father: {fileID: 1023661553}
  m_LocalEulerAnglesHint: {x: 0, y: 0, z: 0}
  m_AnchorMin: {x: 0, y: 0}
  m_AnchorMax: {x: 1, y: 1}
  m_AnchoredPosition: {x: 0, y: 0}
  m_SizeDelta: {x: 0, y: 0}
  m_Pivot: {x: 0.5, y: 0.5}
--- !u!114 &297247866
MonoBehaviour:
  m_ObjectHideFlags: 0
  m_CorrespondingSourceObject: {fileID: 0}
  m_PrefabInstance: {fileID: 0}
  m_PrefabAsset: {fileID: 0}
  m_GameObject: {fileID: 297247864}
  m_Enabled: 1
  m_EditorHideFlags: 0
  m_Script: {fileID: 11500000, guid: f4688fdb7df04437aeb418b961361dc5, type: 3}
  m_Name: 
  m_EditorClassIdentifier: 
  m_Material: {fileID: 0}
  m_Color: {r: 1, g: 1, b: 1, a: 1}
  m_RaycastTarget: 1
  m_RaycastPadding: {x: 0, y: 0, z: 0, w: 0}
  m_Maskable: 1
  m_OnCullStateChanged:
    m_PersistentCalls:
      m_Calls: []
  m_text: Get IK
  m_isRightToLeft: 0
  m_fontAsset: {fileID: 11400000, guid: 8f586378b4e144a9851e7b34d9b748ee, type: 2}
  m_sharedMaterial: {fileID: 2180264, guid: 8f586378b4e144a9851e7b34d9b748ee, type: 2}
  m_fontSharedMaterials: []
  m_fontMaterial: {fileID: 0}
  m_fontMaterials: []
  m_fontColor32:
    serializedVersion: 2
    rgba: 4281479730
  m_fontColor: {r: 0.19607843, g: 0.19607843, b: 0.19607843, a: 1}
  m_enableVertexGradient: 0
  m_colorMode: 3
  m_fontColorGradient:
    topLeft: {r: 1, g: 1, b: 1, a: 1}
    topRight: {r: 1, g: 1, b: 1, a: 1}
    bottomLeft: {r: 1, g: 1, b: 1, a: 1}
    bottomRight: {r: 1, g: 1, b: 1, a: 1}
  m_fontColorGradientPreset: {fileID: 0}
  m_spriteAsset: {fileID: 0}
  m_tintAllSprites: 0
  m_StyleSheet: {fileID: 0}
  m_TextStyleHashCode: -1183493901
  m_overrideHtmlColors: 0
  m_faceColor:
    serializedVersion: 2
    rgba: 4294967295
  m_fontSize: 24
  m_fontSizeBase: 24
  m_fontWeight: 400
  m_enableAutoSizing: 0
  m_fontSizeMin: 0
  m_fontSizeMax: 0
  m_fontStyle: 0
  m_HorizontalAlignment: 2
  m_VerticalAlignment: 512
  m_textAlignment: 65535
  m_characterSpacing: 0
  m_wordSpacing: 0
  m_lineSpacing: 0
  m_lineSpacingMax: 0
  m_paragraphSpacing: 0
  m_charWidthMaxAdj: 0
  m_enableWordWrapping: 0
  m_wordWrappingRatios: 0.4
  m_overflowMode: 0
  m_linkedTextComponent: {fileID: 0}
  parentLinkedComponent: {fileID: 0}
  m_enableKerning: 0
  m_enableExtraPadding: 0
  checkPaddingRequired: 0
  m_isRichText: 1
  m_parseCtrlCharacters: 1
  m_isOrthographic: 1
  m_isCullingEnabled: 0
  m_horizontalMapping: 0
  m_verticalMapping: 0
  m_uvLineOffset: 0
  m_geometrySortingOrder: 0
  m_IsTextObjectScaleStatic: 0
  m_VertexBufferAutoSizeReduction: 0
  m_useMaxVisibleDescender: 1
  m_pageToDisplay: 1
  m_margin: {x: 0, y: 0, z: 0, w: 0}
  m_isUsingLegacyAnimationComponent: 0
  m_isVolumetricText: 0
  m_hasFontAssetChanged: 0
  m_baseMaterial: {fileID: 0}
  m_maskOffset: {x: 0, y: 0, z: 0, w: 0}
--- !u!222 &297247867
CanvasRenderer:
  m_ObjectHideFlags: 0
  m_CorrespondingSourceObject: {fileID: 0}
  m_PrefabInstance: {fileID: 0}
  m_PrefabAsset: {fileID: 0}
  m_GameObject: {fileID: 297247864}
  m_CullTransparentMesh: 1
--- !u!1 &436650965
GameObject:
  m_ObjectHideFlags: 0
  m_CorrespondingSourceObject: {fileID: 0}
  m_PrefabInstance: {fileID: 0}
  m_PrefabAsset: {fileID: 0}
  serializedVersion: 6
  m_Component:
  - component: {fileID: 436650968}
  - component: {fileID: 436650967}
  - component: {fileID: 436650966}
  m_Layer: 0
  m_Name: EventSystem
  m_TagString: Untagged
  m_Icon: {fileID: 0}
  m_NavMeshLayer: 0
  m_StaticEditorFlags: 0
  m_IsActive: 1
--- !u!114 &436650966
MonoBehaviour:
  m_ObjectHideFlags: 0
  m_CorrespondingSourceObject: {fileID: 0}
  m_PrefabInstance: {fileID: 0}
  m_PrefabAsset: {fileID: 0}
  m_GameObject: {fileID: 436650965}
  m_Enabled: 1
  m_EditorHideFlags: 0
  m_Script: {fileID: 11500000, guid: 4f231c4fb786f3946a6b90b886c48677, type: 3}
  m_Name: 
  m_EditorClassIdentifier: 
  m_SendPointerHoverToParent: 1
  m_HorizontalAxis: Horizontal
  m_VerticalAxis: Vertical
  m_SubmitButton: Submit
  m_CancelButton: Cancel
  m_InputActionsPerSecond: 10
  m_RepeatDelay: 0.5
  m_ForceModuleActive: 0
--- !u!114 &436650967
MonoBehaviour:
  m_ObjectHideFlags: 0
  m_CorrespondingSourceObject: {fileID: 0}
  m_PrefabInstance: {fileID: 0}
  m_PrefabAsset: {fileID: 0}
  m_GameObject: {fileID: 436650965}
  m_Enabled: 1
  m_EditorHideFlags: 0
  m_Script: {fileID: 11500000, guid: 76c392e42b5098c458856cdf6ecaaaa1, type: 3}
  m_Name: 
  m_EditorClassIdentifier: 
  m_FirstSelected: {fileID: 0}
  m_sendNavigationEvents: 1
  m_DragThreshold: 10
--- !u!4 &436650968
Transform:
  m_ObjectHideFlags: 0
  m_CorrespondingSourceObject: {fileID: 0}
  m_PrefabInstance: {fileID: 0}
  m_PrefabAsset: {fileID: 0}
  m_GameObject: {fileID: 436650965}
  serializedVersion: 2
  m_LocalRotation: {x: 0, y: 0, z: 0, w: 1}
  m_LocalPosition: {x: 0, y: 0, z: 0}
  m_LocalScale: {x: 1, y: 1, z: 1}
  m_ConstrainProportionsScale: 0
  m_Children: []
  m_Father: {fileID: 0}
  m_LocalEulerAnglesHint: {x: 0, y: 0, z: 0}
--- !u!1 &705507993
GameObject:
  m_ObjectHideFlags: 0
  m_CorrespondingSourceObject: {fileID: 0}
  m_PrefabInstance: {fileID: 0}
  m_PrefabAsset: {fileID: 0}
  serializedVersion: 6
  m_Component:
  - component: {fileID: 705507995}
  - component: {fileID: 705507994}
  m_Layer: 0
  m_Name: Directional Light
  m_TagString: Untagged
  m_Icon: {fileID: 0}
  m_NavMeshLayer: 0
  m_StaticEditorFlags: 0
  m_IsActive: 1
--- !u!108 &705507994
Light:
  m_ObjectHideFlags: 0
  m_CorrespondingSourceObject: {fileID: 0}
  m_PrefabInstance: {fileID: 0}
  m_PrefabAsset: {fileID: 0}
  m_GameObject: {fileID: 705507993}
  m_Enabled: 1
  serializedVersion: 10
  m_Type: 1
  m_Shape: 0
  m_Color: {r: 1, g: 0.95686275, b: 0.8392157, a: 1}
  m_Intensity: 1
  m_Range: 10
  m_SpotAngle: 30
  m_InnerSpotAngle: 21.80208
  m_CookieSize: 10
  m_Shadows:
    m_Type: 2
    m_Resolution: -1
    m_CustomResolution: -1
    m_Strength: 1
    m_Bias: 0.05
    m_NormalBias: 0.4
    m_NearPlane: 0.2
    m_CullingMatrixOverride:
      e00: 1
      e01: 0
      e02: 0
      e03: 0
      e10: 0
      e11: 1
      e12: 0
      e13: 0
      e20: 0
      e21: 0
      e22: 1
      e23: 0
      e30: 0
      e31: 0
      e32: 0
      e33: 1
    m_UseCullingMatrixOverride: 0
  m_Cookie: {fileID: 0}
  m_DrawHalo: 0
  m_Flare: {fileID: 0}
  m_RenderMode: 0
  m_CullingMask:
    serializedVersion: 2
    m_Bits: 4294967295
  m_RenderingLayerMask: 1
  m_Lightmapping: 1
  m_LightShadowCasterMode: 0
  m_AreaSize: {x: 1, y: 1}
  m_BounceIntensity: 1
  m_ColorTemperature: 6570
  m_UseColorTemperature: 0
  m_BoundingSphereOverride: {x: 0, y: 0, z: 0, w: 0}
  m_UseBoundingSphereOverride: 0
  m_UseViewFrustumForShadowCasterCull: 1
  m_ShadowRadius: 0
  m_ShadowAngle: 0
--- !u!4 &705507995
Transform:
  m_ObjectHideFlags: 0
  m_CorrespondingSourceObject: {fileID: 0}
  m_PrefabInstance: {fileID: 0}
  m_PrefabAsset: {fileID: 0}
  m_GameObject: {fileID: 705507993}
  serializedVersion: 2
  m_LocalRotation: {x: 0.40821788, y: -0.23456968, z: 0.10938163, w: 0.8754261}
  m_LocalPosition: {x: 0, y: 3, z: 0}
  m_LocalScale: {x: 1, y: 1, z: 1}
  m_ConstrainProportionsScale: 0
  m_Children: []
  m_Father: {fileID: 0}
  m_LocalEulerAnglesHint: {x: 50, y: -30, z: 0}
--- !u!1 &963194225
GameObject:
  m_ObjectHideFlags: 0
  m_CorrespondingSourceObject: {fileID: 0}
  m_PrefabInstance: {fileID: 0}
  m_PrefabAsset: {fileID: 0}
  serializedVersion: 6
  m_Component:
  - component: {fileID: 963194228}
  - component: {fileID: 963194227}
  - component: {fileID: 963194226}
  m_Layer: 0
  m_Name: Main Camera
  m_TagString: MainCamera
  m_Icon: {fileID: 0}
  m_NavMeshLayer: 0
  m_StaticEditorFlags: 0
  m_IsActive: 1
--- !u!81 &963194226
AudioListener:
  m_ObjectHideFlags: 0
  m_CorrespondingSourceObject: {fileID: 0}
  m_PrefabInstance: {fileID: 0}
  m_PrefabAsset: {fileID: 0}
  m_GameObject: {fileID: 963194225}
  m_Enabled: 1
--- !u!20 &963194227
Camera:
  m_ObjectHideFlags: 0
  m_CorrespondingSourceObject: {fileID: 0}
  m_PrefabInstance: {fileID: 0}
  m_PrefabAsset: {fileID: 0}
  m_GameObject: {fileID: 963194225}
  m_Enabled: 1
  serializedVersion: 2
  m_ClearFlags: 1
  m_BackGroundColor: {r: 0.19215687, g: 0.3019608, b: 0.4745098, a: 0}
  m_projectionMatrixMode: 1
  m_GateFitMode: 2
  m_FOVAxisMode: 0
  m_Iso: 200
  m_ShutterSpeed: 0.005
  m_Aperture: 16
  m_FocusDistance: 10
  m_FocalLength: 50
  m_BladeCount: 5
  m_Curvature: {x: 2, y: 11}
  m_BarrelClipping: 0.25
  m_Anamorphism: 0
  m_SensorSize: {x: 36, y: 24}
  m_LensShift: {x: 0, y: 0}
  m_NormalizedViewPortRect:
    serializedVersion: 2
    x: 0
    y: 0
    width: 1
    height: 1
  near clip plane: 0.3
  far clip plane: 1000
  field of view: 60
  orthographic: 0
  orthographic size: 5
  m_Depth: -1
  m_CullingMask:
    serializedVersion: 2
    m_Bits: 4294967295
  m_RenderingPath: -1
  m_TargetTexture: {fileID: 0}
  m_TargetDisplay: 0
  m_TargetEye: 3
  m_HDR: 1
  m_AllowMSAA: 1
  m_AllowDynamicResolution: 0
  m_ForceIntoRT: 0
  m_OcclusionCulling: 1
  m_StereoConvergence: 10
  m_StereoSeparation: 0.022
--- !u!4 &963194228
Transform:
  m_ObjectHideFlags: 0
  m_CorrespondingSourceObject: {fileID: 0}
  m_PrefabInstance: {fileID: 0}
  m_PrefabAsset: {fileID: 0}
  m_GameObject: {fileID: 963194225}
  serializedVersion: 2
  m_LocalRotation: {x: 0, y: 0, z: 0, w: 1}
  m_LocalPosition: {x: 0, y: 1, z: -10}
  m_LocalScale: {x: 1, y: 1, z: 1}
  m_ConstrainProportionsScale: 0
  m_Children: []
  m_Father: {fileID: 0}
  m_LocalEulerAnglesHint: {x: 0, y: 0, z: 0}
--- !u!1 &1023661552
GameObject:
  m_ObjectHideFlags: 0
  m_CorrespondingSourceObject: {fileID: 0}
  m_PrefabInstance: {fileID: 0}
  m_PrefabAsset: {fileID: 0}
  serializedVersion: 6
  m_Component:
  - component: {fileID: 1023661553}
  - component: {fileID: 1023661556}
  - component: {fileID: 1023661555}
  - component: {fileID: 1023661554}
  m_Layer: 5
  m_Name: Button
  m_TagString: Untagged
  m_Icon: {fileID: 0}
  m_NavMeshLayer: 0
  m_StaticEditorFlags: 0
  m_IsActive: 1
--- !u!224 &1023661553
RectTransform:
  m_ObjectHideFlags: 0
  m_CorrespondingSourceObject: {fileID: 0}
  m_PrefabInstance: {fileID: 0}
  m_PrefabAsset: {fileID: 0}
  m_GameObject: {fileID: 1023661552}
  m_LocalRotation: {x: 0, y: 0, z: 0, w: 1}
  m_LocalPosition: {x: 0, y: 0, z: 0}
  m_LocalScale: {x: 1, y: 1, z: 1}
  m_ConstrainProportionsScale: 0
  m_Children:
  - {fileID: 297247865}
  m_Father: {fileID: 2123929362}
  m_LocalEulerAnglesHint: {x: 0, y: 0, z: 0}
  m_AnchorMin: {x: 0.5, y: 0.5}
  m_AnchorMax: {x: 0.5, y: 0.5}
  m_AnchoredPosition: {x: 0, y: 0}
  m_SizeDelta: {x: 160, y: 30}
  m_Pivot: {x: 0.5, y: 0.5}
--- !u!114 &1023661554
MonoBehaviour:
  m_ObjectHideFlags: 0
  m_CorrespondingSourceObject: {fileID: 0}
  m_PrefabInstance: {fileID: 0}
  m_PrefabAsset: {fileID: 0}
  m_GameObject: {fileID: 1023661552}
  m_Enabled: 1
  m_EditorHideFlags: 0
  m_Script: {fileID: 11500000, guid: 4e29b1a8efbd4b44bb3f3716e73f07ff, type: 3}
  m_Name: 
  m_EditorClassIdentifier: 
  m_Navigation:
    m_Mode: 3
    m_WrapAround: 0
    m_SelectOnUp: {fileID: 0}
    m_SelectOnDown: {fileID: 0}
    m_SelectOnLeft: {fileID: 0}
    m_SelectOnRight: {fileID: 0}
  m_Transition: 1
  m_Colors:
    m_NormalColor: {r: 1, g: 1, b: 1, a: 1}
    m_HighlightedColor: {r: 0.9607843, g: 0.9607843, b: 0.9607843, a: 1}
    m_PressedColor: {r: 0.78431374, g: 0.78431374, b: 0.78431374, a: 1}
    m_SelectedColor: {r: 0.9607843, g: 0.9607843, b: 0.9607843, a: 1}
    m_DisabledColor: {r: 0.78431374, g: 0.78431374, b: 0.78431374, a: 0.5019608}
    m_ColorMultiplier: 1
    m_FadeDuration: 0.1
  m_SpriteState:
    m_HighlightedSprite: {fileID: 0}
    m_PressedSprite: {fileID: 0}
    m_SelectedSprite: {fileID: 0}
    m_DisabledSprite: {fileID: 0}
  m_AnimationTriggers:
    m_NormalTrigger: Normal
    m_HighlightedTrigger: Highlighted
    m_PressedTrigger: Pressed
    m_SelectedTrigger: Selected
    m_DisabledTrigger: Disabled
  m_Interactable: 1
  m_TargetGraphic: {fileID: 1023661555}
  m_OnClick:
    m_PersistentCalls:
      m_Calls:
      - m_Target: {fileID: 1048981094}
        m_TargetAssemblyTypeName: IK.IKTest, Assembly-CSharp
        m_MethodName: GetJointAngles
        m_Mode: 1
        m_Arguments:
          m_ObjectArgument: {fileID: 0}
          m_ObjectArgumentAssemblyTypeName: UnityEngine.Object, UnityEngine
          m_IntArgument: 0
          m_FloatArgument: 0
          m_StringArgument: 
          m_BoolArgument: 0
        m_CallState: 2
--- !u!114 &1023661555
MonoBehaviour:
  m_ObjectHideFlags: 0
  m_CorrespondingSourceObject: {fileID: 0}
  m_PrefabInstance: {fileID: 0}
  m_PrefabAsset: {fileID: 0}
  m_GameObject: {fileID: 1023661552}
  m_Enabled: 1
  m_EditorHideFlags: 0
  m_Script: {fileID: 11500000, guid: fe87c0e1cc204ed48ad3b37840f39efc, type: 3}
  m_Name: 
  m_EditorClassIdentifier: 
  m_Material: {fileID: 0}
  m_Color: {r: 1, g: 1, b: 1, a: 1}
  m_RaycastTarget: 1
  m_RaycastPadding: {x: 0, y: 0, z: 0, w: 0}
  m_Maskable: 1
  m_OnCullStateChanged:
    m_PersistentCalls:
      m_Calls: []
  m_Sprite: {fileID: 10905, guid: 0000000000000000f000000000000000, type: 0}
  m_Type: 1
  m_PreserveAspect: 0
  m_FillCenter: 1
  m_FillMethod: 4
  m_FillAmount: 1
  m_FillClockwise: 1
  m_FillOrigin: 0
  m_UseSpriteMesh: 0
  m_PixelsPerUnitMultiplier: 1
--- !u!222 &1023661556
CanvasRenderer:
  m_ObjectHideFlags: 0
  m_CorrespondingSourceObject: {fileID: 0}
  m_PrefabInstance: {fileID: 0}
  m_PrefabAsset: {fileID: 0}
  m_GameObject: {fileID: 1023661552}
  m_CullTransparentMesh: 1
--- !u!1 &1048981093
GameObject:
  m_ObjectHideFlags: 0
  m_CorrespondingSourceObject: {fileID: 0}
  m_PrefabInstance: {fileID: 0}
  m_PrefabAsset: {fileID: 0}
  serializedVersion: 6
  m_Component:
  - component: {fileID: 1048981095}
  - component: {fileID: 1048981094}
  m_Layer: 0
  m_Name: IKHandler
  m_TagString: Untagged
  m_Icon: {fileID: 0}
  m_NavMeshLayer: 0
  m_StaticEditorFlags: 0
  m_IsActive: 1
--- !u!114 &1048981094
MonoBehaviour:
  m_ObjectHideFlags: 0
  m_CorrespondingSourceObject: {fileID: 0}
  m_PrefabInstance: {fileID: 0}
  m_PrefabAsset: {fileID: 0}
  m_GameObject: {fileID: 1048981093}
  m_Enabled: 1
  m_EditorHideFlags: 0
  m_Script: {fileID: 11500000, guid: 273b21c6b916b315da7bbda6ca6dd9fb, type: 3}
  m_Name: 
  m_EditorClassIdentifier: 
  urdfString: <robot name="ur_ur5_robot">         <transmission name="shoulder_lift_trans">    
    <type>transmission_interface/SimpleTransmission</type>     <joint name="shoulder_lift_joint">      
    <hardwareInterface>hardware_interface/PositionJointInterface</hardwareInterface>    
    </joint>     <actuator name="shoulder_lift_motor">       <mechanicalReduction>1</mechanicalReduction>    
    </actuator>   </transmission>   <transmission name="wrist_1_trans">     <type>transmission_interface/SimpleTransmission</type>    
    <joint name="wrist_1_joint">       <hardwareInterface>hardware_interface/PositionJointInterface</hardwareInterface>    
    </joint>     <actuator name="wrist_1_motor">       <mechanicalReduction>1</mechanicalReduction>    
    </actuator>   </transmission>   <transmission name="wrist_3_trans">     <type>transmission_interface/SimpleTransmission</type>    
    <joint name="wrist_3_joint">       <hardwareInterface>hardware_interface/PositionJointInterface</hardwareInterface>    
    </joint>     <actuator name="wrist_3_motor">       <mechanicalReduction>1</mechanicalReduction>    
    </actuator>   </transmission>      <link name="base_link" />   <link name="base_link_inertia">    
    <visual>       <origin rpy="0 0 3.141592653589793" xyz="0 0 0" />       <geometry>        
    <mesh filename="0_base.dae" />       </geometry>       <material name="LightGrey">        
    <color rgba="0.7 0.7 0.7 1.0" />       </material>     </visual>     <inertial>      
    <mass value="4.0" />       <origin rpy="0 0 0" xyz="0 0 0" />       <inertia
    ixx="0.00443333156" ixy="0.0" ixz="0.0" iyy="0.00443333156" iyz="0.0" izz="0.0072"
    />     </inertial>   </link>   <link name="shoulder_link">     <visual>      
    <origin rpy="0 0 3.141592653589793" xyz="0 0 0" />       <geometry>         <mesh
    filename="1_shoulder.dae" />       </geometry>       <material name="LightGrey">        
    <color rgba="0.7 0.7 0.7 1.0" />       </material>     </visual>     <inertial>      
    <mass value="3.7" />       <origin rpy="0 0 0" xyz="0 0 0" />       <inertia
    ixx="0.014972352344389999" ixy="0.0" ixz="0.0" iyy="0.014972352344389999" iyz="0.0"
    izz="0.01040625" />     </inertial>   </link>   <link name="upper_arm_link">    
    <visual>       <origin rpy="1.5707963267948966 0 -1.5707963267948966" xyz="0
    0 0.13585" />       <geometry>         <mesh filename="2_upperarm.dae" />      
    </geometry>       <material name="LightGrey">         <color rgba="0.7 0.7 0.7
    1.0" />       </material>     </visual>     <inertial>       <mass value="8.393"
    />       <origin rpy="0 1.5707963267948966 0" xyz="-0.2125 0.0 0.136" />      
    <inertia ixx="0.1338857818623325" ixy="0.0" ixz="0.0" iyy="0.1338857818623325"
    iyz="0.0" izz="0.0151074" />     </inertial>   </link>   <link name="forearm_link">    
    <visual>       <origin rpy="1.5707963267948966 0 -1.5707963267948966" xyz="0
    0 0.0165" />       <geometry>         <mesh filename="3_forearm.dae" />      
    </geometry>       <material name="LightGrey">         <color rgba="0.7 0.7 0.7
    1.0" />       </material>     </visual>     <inertial>       <mass value="2.275"
    />       <origin rpy="0 1.5707963267948966 0" xyz="-0.196125 0.0 0.0165" />      
    <inertia ixx="0.03121679102890359" ixy="0.0" ixz="0.0" iyy="0.03121679102890359"
    iyz="0.0" izz="0.004095" />     </inertial>   </link>   <link name="wrist_1_link">    
    <visual>              <origin rpy="1.5707963267948966 0 0" xyz="0 0 -0.093" />      
    <geometry>         <mesh filename="4_wrist1.dae" />       </geometry>       <material
    name="LightGrey">         <color rgba="0.7 0.7 0.7 1.0" />       </material>    
    </visual>     <inertial>       <mass value="1.219" />       <origin rpy="0 0
    0" xyz="0 0 0" />       <inertia ixx="0.0020138887777775" ixy="0.0" ixz="0.0"
    iyy="0.0020138887777775" iyz="0.0" izz="0.0021942" />     </inertial>   </link>  
    <link name="wrist_2_link">     <visual>       <origin rpy="0 0 0" xyz="0 0 -0.095"
    />       <geometry>         <mesh filename="5_wrist2.dae" />       </geometry>      
    <material name="LightGrey">         <color rgba="0.7 0.7 0.7 1.0" />       </material>    
    </visual>     <inertial>       <mass value="1.219" />       <origin rpy="0 0
    0" xyz="0 0 0" />       <inertia ixx="0.0018310388509175" ixy="0.0" ixz="0.0"
    iyy="0.0018310388509175" iyz="0.0" izz="0.0021942" />     </inertial>   </link>  
    <link name="wrist_3_link">     <visual>       <origin rpy="1.5707963267948966
    0 0" xyz="0 0 -0.0818" />       <geometry>         <mesh filename="6_wrist3.dae"
    />       </geometry>       <material name="LightGrey">         <color rgba="0.7
    0.7 0.7 1.0" />       </material>     </visual>     <inertial>       <mass value="0.1879"
    />       <origin rpy="0 0 0" xyz="0.0 0.0 -0.01525" />       <inertia ixx="8.062472608343e-05"
    ixy="0.0" ixz="0.0" iyy="8.062472608343e-05" iyz="0.0" izz="0.0001321171875"
    />     </inertial>   </link>      <joint name="base_link-base_link_inertia" type="fixed">    
    <parent link="base_link" />     <child link="base_link_inertia" />          <origin
    rpy="0 0 3.141592653589793" xyz="0 0 0" />   </joint>   <joint name="shoulder_pan_joint"
    type="revolute">     <parent link="base_link_inertia" />     <child link="shoulder_link"
    />     <origin rpy="0 0 0" xyz="0 0 0.089159" />     <axis xyz="0 0 1" />    
    <limit effort="150.0" lower="-6.283185307179586" upper="6.283185307179586" velocity="3.141592653589793"
    />     <dynamics damping="0" friction="0" />   </joint>   <joint name="shoulder_lift_joint"
    type="revolute">     <parent link="shoulder_link" />     <child link="upper_arm_link"
    />     <origin rpy="1.570796327 0 0" xyz="0 0 0" />     <axis xyz="0 0 1" />    
    <limit effort="150.0" lower="-6.283185307179586" upper="6.283185307179586" velocity="3.141592653589793"
    />     <dynamics damping="0" friction="0" />   </joint>   <joint name="elbow_joint"
    type="revolute">     <parent link="upper_arm_link" />     <child link="forearm_link"
    />     <origin rpy="0 0 0" xyz="-0.425 0 0" />     <axis xyz="0 0 1" />     <limit
    effort="150.0" lower="-3.141592653589793" upper="3.141592653589793" velocity="3.141592653589793"
    />     <dynamics damping="0" friction="0" />   </joint>   <joint name="wrist_1_joint"
    type="revolute">     <parent link="forearm_link" />     <child link="wrist_1_link"
    />     <origin rpy="0 0 0" xyz="-0.39225 0 0.10915" />     <axis xyz="0 0 1"
    />     <limit effort="28.0" lower="-6.283185307179586" upper="6.283185307179586"
    velocity="3.141592653589793" />     <dynamics damping="0" friction="0" />   </joint>  
    <joint name="wrist_2_joint" type="revolute">     <parent link="wrist_1_link"
    />     <child link="wrist_2_link" />     <origin rpy="1.570796327 0 0" xyz="0
    -0.09465 -1.941303950897609e-11" />     <axis xyz="0 0 1" />     <limit effort="28.0"
    lower="-6.283185307179586" upper="6.283185307179586" velocity="3.141592653589793"
    />     <dynamics damping="0" friction="0" />   </joint>   <joint name="wrist_3_joint"
    type="revolute">     <parent link="wrist_2_link" />     <child link="wrist_3_link"
    />     <origin rpy="1.570796326589793 3.141592653589793 3.141592653589793" xyz="0
    0.0823 -1.688001216681175e-11" />     <axis xyz="0 0 1" />     <limit effort="28.0"
    lower="-6.283185307179586" upper="6.283185307179586" velocity="3.141592653589793"
    />     <dynamics damping="0" friction="0" />   </joint>      <link name="base"
    />   <joint name="base_link-base_fixed_joint" type="fixed">          <origin
    rpy="0 0 3.141592653589793" xyz="0 0 0" />     <parent link="base_link" />    
    <child link="base" />   </joint>      <link name="flange" />   <joint name="wrist_3-flange"
    type="fixed">     <parent link="wrist_3_link" />     <child link="flange" />    
    <origin rpy="0 -1.5707963267948966 -1.5707963267948966" xyz="0 0 0" />   </joint>     
    <link name="tool0" />   <joint name="flange-tool0" type="fixed">          <origin
    rpy="1.5707963267948966 0 1.5707963267948966" xyz="0 0 0" />     <parent link="flange"
    />     <child link="tool0" />   </joint> </robot>
  baseLink: base_link_inertia
  endEffectorLink: tool0
  outputText: {fileID: 1832414052}
--- !u!4 &1048981095
Transform:
  m_ObjectHideFlags: 0
  m_CorrespondingSourceObject: {fileID: 0}
  m_PrefabInstance: {fileID: 0}
  m_PrefabAsset: {fileID: 0}
  m_GameObject: {fileID: 1048981093}
  serializedVersion: 2
  m_LocalRotation: {x: 0, y: 0, z: 0, w: 1}
  m_LocalPosition: {x: 0, y: 0, z: 0}
  m_LocalScale: {x: 1, y: 1, z: 1}
  m_ConstrainProportionsScale: 0
  m_Children: []
  m_Father: {fileID: 0}
  m_LocalEulerAnglesHint: {x: 0, y: 0, z: 0}
--- !u!1 &1832414050
GameObject:
  m_ObjectHideFlags: 0
  m_CorrespondingSourceObject: {fileID: 0}
  m_PrefabInstance: {fileID: 0}
  m_PrefabAsset: {fileID: 0}
  serializedVersion: 6
  m_Component:
  - component: {fileID: 1832414051}
  - component: {fileID: 1832414053}
  - component: {fileID: 1832414052}
  m_Layer: 5
  m_Name: Text (TMP)
  m_TagString: Untagged
  m_Icon: {fileID: 0}
  m_NavMeshLayer: 0
  m_StaticEditorFlags: 0
  m_IsActive: 1
--- !u!224 &1832414051
RectTransform:
  m_ObjectHideFlags: 0
  m_CorrespondingSourceObject: {fileID: 0}
  m_PrefabInstance: {fileID: 0}
  m_PrefabAsset: {fileID: 0}
  m_GameObject: {fileID: 1832414050}
  m_LocalRotation: {x: 0, y: 0, z: 0, w: 1}
  m_LocalPosition: {x: 0, y: 0, z: 0}
  m_LocalScale: {x: 1, y: 1, z: 1}
  m_ConstrainProportionsScale: 0
  m_Children: []
  m_Father: {fileID: 2123929362}
  m_LocalEulerAnglesHint: {x: 0, y: 0, z: 0}
  m_AnchorMin: {x: 0.5, y: 0.5}
  m_AnchorMax: {x: 0.5, y: 0.5}
  m_AnchoredPosition: {x: -183, y: -69}
  m_SizeDelta: {x: 200, y: 50}
  m_Pivot: {x: 0.5, y: 0.5}
--- !u!114 &1832414052
MonoBehaviour:
  m_ObjectHideFlags: 0
  m_CorrespondingSourceObject: {fileID: 0}
  m_PrefabInstance: {fileID: 0}
  m_PrefabAsset: {fileID: 0}
  m_GameObject: {fileID: 1832414050}
  m_Enabled: 1
  m_EditorHideFlags: 0
  m_Script: {fileID: 11500000, guid: f4688fdb7df04437aeb418b961361dc5, type: 3}
  m_Name: 
  m_EditorClassIdentifier: 
  m_Material: {fileID: 0}
  m_Color: {r: 1, g: 1, b: 1, a: 1}
  m_RaycastTarget: 1
  m_RaycastPadding: {x: 0, y: 0, z: 0, w: 0}
  m_Maskable: 1
  m_OnCullStateChanged:
    m_PersistentCalls:
      m_Calls: []
  m_text: <ik result>
  m_isRightToLeft: 0
  m_fontAsset: {fileID: 11400000, guid: 8f586378b4e144a9851e7b34d9b748ee, type: 2}
  m_sharedMaterial: {fileID: 2180264, guid: 8f586378b4e144a9851e7b34d9b748ee, type: 2}
  m_fontSharedMaterials: []
  m_fontMaterial: {fileID: 0}
  m_fontMaterials: []
  m_fontColor32:
    serializedVersion: 2
    rgba: 4294967295
  m_fontColor: {r: 1, g: 1, b: 1, a: 1}
  m_enableVertexGradient: 0
  m_colorMode: 3
  m_fontColorGradient:
    topLeft: {r: 1, g: 1, b: 1, a: 1}
    topRight: {r: 1, g: 1, b: 1, a: 1}
    bottomLeft: {r: 1, g: 1, b: 1, a: 1}
    bottomRight: {r: 1, g: 1, b: 1, a: 1}
  m_fontColorGradientPreset: {fileID: 0}
  m_spriteAsset: {fileID: 0}
  m_tintAllSprites: 0
  m_StyleSheet: {fileID: 0}
  m_TextStyleHashCode: -1183493901
  m_overrideHtmlColors: 0
  m_faceColor:
    serializedVersion: 2
    rgba: 4294967295
  m_fontSize: 20
  m_fontSizeBase: 20
  m_fontWeight: 400
  m_enableAutoSizing: 0
  m_fontSizeMin: 18
  m_fontSizeMax: 72
  m_fontStyle: 0
  m_HorizontalAlignment: 2
  m_VerticalAlignment: 512
  m_textAlignment: 65535
  m_characterSpacing: 0
  m_wordSpacing: 0
  m_lineSpacing: 0
  m_lineSpacingMax: 0
  m_paragraphSpacing: 0
  m_charWidthMaxAdj: 0
  m_enableWordWrapping: 1
  m_wordWrappingRatios: 0.4
  m_overflowMode: 0
  m_linkedTextComponent: {fileID: 0}
  parentLinkedComponent: {fileID: 0}
  m_enableKerning: 1
  m_enableExtraPadding: 0
  checkPaddingRequired: 0
  m_isRichText: 1
  m_parseCtrlCharacters: 1
  m_isOrthographic: 1
  m_isCullingEnabled: 0
  m_horizontalMapping: 0
  m_verticalMapping: 0
  m_uvLineOffset: 0
  m_geometrySortingOrder: 0
  m_IsTextObjectScaleStatic: 0
  m_VertexBufferAutoSizeReduction: 0
  m_useMaxVisibleDescender: 1
  m_pageToDisplay: 1
  m_margin: {x: 0, y: 0, z: -366.4922, w: 0}
  m_isUsingLegacyAnimationComponent: 0
  m_isVolumetricText: 0
  m_hasFontAssetChanged: 0
  m_baseMaterial: {fileID: 0}
  m_maskOffset: {x: 0, y: 0, z: 0, w: 0}
--- !u!222 &1832414053
CanvasRenderer:
  m_ObjectHideFlags: 0
  m_CorrespondingSourceObject: {fileID: 0}
  m_PrefabInstance: {fileID: 0}
  m_PrefabAsset: {fileID: 0}
  m_GameObject: {fileID: 1832414050}
  m_CullTransparentMesh: 1
--- !u!1 &2123929358
GameObject:
  m_ObjectHideFlags: 0
  m_CorrespondingSourceObject: {fileID: 0}
  m_PrefabInstance: {fileID: 0}
  m_PrefabAsset: {fileID: 0}
  serializedVersion: 6
  m_Component:
  - component: {fileID: 2123929362}
  - component: {fileID: 2123929361}
  - component: {fileID: 2123929360}
  - component: {fileID: 2123929359}
  m_Layer: 5
  m_Name: Canvas
  m_TagString: Untagged
  m_Icon: {fileID: 0}
  m_NavMeshLayer: 0
  m_StaticEditorFlags: 0
  m_IsActive: 1
--- !u!114 &2123929359
MonoBehaviour:
  m_ObjectHideFlags: 0
  m_CorrespondingSourceObject: {fileID: 0}
  m_PrefabInstance: {fileID: 0}
  m_PrefabAsset: {fileID: 0}
  m_GameObject: {fileID: 2123929358}
  m_Enabled: 1
  m_EditorHideFlags: 0
  m_Script: {fileID: 11500000, guid: dc42784cf147c0c48a680349fa168899, type: 3}
  m_Name: 
  m_EditorClassIdentifier: 
  m_IgnoreReversedGraphics: 1
  m_BlockingObjects: 0
  m_BlockingMask:
    serializedVersion: 2
    m_Bits: 4294967295
--- !u!114 &2123929360
MonoBehaviour:
  m_ObjectHideFlags: 0
  m_CorrespondingSourceObject: {fileID: 0}
  m_PrefabInstance: {fileID: 0}
  m_PrefabAsset: {fileID: 0}
  m_GameObject: {fileID: 2123929358}
  m_Enabled: 1
  m_EditorHideFlags: 0
  m_Script: {fileID: 11500000, guid: 0cd44c1031e13a943bb63640046fad76, type: 3}
  m_Name: 
  m_EditorClassIdentifier: 
  m_UiScaleMode: 0
  m_ReferencePixelsPerUnit: 100
  m_ScaleFactor: 1
  m_ReferenceResolution: {x: 800, y: 600}
  m_ScreenMatchMode: 0
  m_MatchWidthOrHeight: 0
  m_PhysicalUnit: 3
  m_FallbackScreenDPI: 96
  m_DefaultSpriteDPI: 96
  m_DynamicPixelsPerUnit: 1
  m_PresetInfoIsWorld: 0
--- !u!223 &2123929361
Canvas:
  m_ObjectHideFlags: 0
  m_CorrespondingSourceObject: {fileID: 0}
  m_PrefabInstance: {fileID: 0}
  m_PrefabAsset: {fileID: 0}
  m_GameObject: {fileID: 2123929358}
  m_Enabled: 1
  serializedVersion: 3
  m_RenderMode: 0
  m_Camera: {fileID: 0}
  m_PlaneDistance: 100
  m_PixelPerfect: 0
  m_ReceivesEvents: 1
  m_OverrideSorting: 0
  m_OverridePixelPerfect: 0
  m_SortingBucketNormalizedSize: 0
  m_VertexColorAlwaysGammaSpace: 0
  m_AdditionalShaderChannelsFlag: 25
  m_UpdateRectTransformForStandalone: 0
  m_SortingLayerID: 0
  m_SortingOrder: 0
  m_TargetDisplay: 0
--- !u!224 &2123929362
RectTransform:
  m_ObjectHideFlags: 0
  m_CorrespondingSourceObject: {fileID: 0}
  m_PrefabInstance: {fileID: 0}
  m_PrefabAsset: {fileID: 0}
  m_GameObject: {fileID: 2123929358}
  m_LocalRotation: {x: 0, y: 0, z: 0, w: 1}
  m_LocalPosition: {x: 0, y: 0, z: 0}
  m_LocalScale: {x: 0, y: 0, z: 0}
  m_ConstrainProportionsScale: 0
  m_Children:
  - {fileID: 1023661553}
  - {fileID: 1832414051}
  m_Father: {fileID: 0}
  m_LocalEulerAnglesHint: {x: 0, y: 0, z: 0}
  m_AnchorMin: {x: 0, y: 0}
  m_AnchorMax: {x: 0, y: 0}
  m_AnchoredPosition: {x: 0, y: 0}
  m_SizeDelta: {x: 0, y: 0}
  m_Pivot: {x: 0, y: 0}
--- !u!1660057539 &9223372036854775807
SceneRoots:
  m_ObjectHideFlags: 0
  m_Roots:
  - {fileID: 963194228}
  - {fileID: 705507995}
  - {fileID: 2123929362}
  - {fileID: 436650968}
  - {fileID: 1048981095}
